Workbook

Sheet Instagram Ads Raw Data
A1: Date | B1: Impressions | C1: Clicks | D1: Spending ($) | E1: Conversions | F1: Revenue ($)
A2: 45658 | B2: 27382 | C2: 483 | D2: 646 | E2: 8 | F2: 1375
A3: 45659 | B3: 99168 | C3: 1561 | D3: 2255 | E3: 35 | F3: 5159
A4: 45660 | B4: 14891 | C4: 273 | D4: 311 | E4: 6 | F4: 717
A5: 45661 | B5: 42989 | C5: 682 | D5: 1192 | E5: 13 | F5: 2969
A6: 45662 | B6: 36381 | C6: 559 | D6: 784 | E6: 13 | F6: 2556
A7: 45663 | B7: 56836 | C7: 1129 | D7: 2015 | E7: 16 | F7: 2697
A8: 45664 | B8: 45926 | C8: 1145 | D8: 1218 | E8: 28 | F8: 5549
A9: 45665 | B9: 43071 | C9: 356 | D9: 602 | E9: 9 | F9: 1395
A10: 45666 | B10: 82343 | C10: 1867 | D10: 2349 | E10: 30 | F10: 5835
A11: 45667 | B11: 76027 | C11: 1249 | D11: 2416 | E11: 16 | F11: 3085
A12: 45668 | B12: 80956 | C12: 733 | D12: 1279 | E12: 18 | F12: 2912
A13: 45669 | B13: 68072 | C13: 1332 | D13: 2367 | E13: 15 | F13: 3234
... A366: 46022 | B366: 83988 | C366: 2183 | D366: 2219 | E366: 41 | F366: 5949

Sheet TikTok Ads Raw Data
A1: =IFERROR(__xludf.DUMMYFUNCTION("IMPORTRANGE(""http://docs.google.com/spreadsheets/d/1sKSMRkQpJAvyzC8Be-4Lkdp2rJaU2wWA6j3l2BYc7kU/edit?gid=846488190#gid=846488190"",""Tiktok Ads Data!A1:F366"")"),"submit_date") -> submit_date | B1: =IFERROR(__xludf.DUMMYFUNCTION("""COMPUTED_VALUE"""),"impressions") -> impressions | C1: =IFERROR(__xludf.DUMMYFUNCTION("""COMPUTED_VALUE"""),"clicks") -> clicks | D1: =IFERROR(__xludf.DUMMYFUNCTION("""COMPUTED_VALUE"""),"spending ($)") -> spending ($) | E1: =IFERROR(__xludf.DUMMYFUNCTION("""COMPUTED_VALUE"""),"conversions") -> conversions | F1: =IFERROR(__xludf.DUMMYFUNCTION("""COMPUTED_VALUE"""),"revenue ($)") -> revenue ($)
A2: =IFERROR(__xludf.DUMMYFUNCTION("""COMPUTED_VALUE"""),45658) -> 45658 | B2: =IFERROR(__xludf.DUMMYFUNCTION("""COMPUTED_VALUE"""),37761) -> 37761 | C2: =IFERROR(__xludf.DUMMYFUNCTION("""COMPUTED_VALUE"""),685) -> 685 | D2: =IFERROR(__xludf.DUMMYFUNCTION("""COMPUTED_VALUE"""),519) -> 519 | E2: =IFERROR(__xludf.DUMMYFUNCTION("""COMPUTED_VALUE"""),11) -> 11 | F2: =IFERROR(__xludf.DUMMYFUNCTION("""COMPUTED_VALUE"""),1711) -> 1711
A3: =IFERROR(__xludf.DUMMYFUNCTION("""COMPUTED_VALUE"""),45659) -> 45659 | B3: =IFERROR(__xludf.DUMMYFUNCTION("""COMPUTED_VALUE"""),113622) -> 113622 | C3: =IFERROR(__xludf.DUMMYFUNCTION("""COMPUTED_VALUE"""),2139) -> 2139 | D3: =IFERROR(__xludf.DUMMYFUNCTION("""COMPUTED_VALUE"""),1923) -> 1923 | E3: =IFERROR(__xludf.DUMMYFUNCTION("""COMPUTED_VALUE"""),50) -> 50 | F3: =IFERROR(__xludf.DUMMYFUNCTION("""COMPUTED_VALUE"""),6262) -> 6262
A4: =IFERROR(__xludf.DUMMYFUNCTION("""COMPUTED_VALUE"""),45660) -> 45660 | B4: =IFERROR(__xludf.DUMMYFUNCTION("""COMPUTED_VALUE"""),25676) -> 25676 | C4: =IFERROR(__xludf.DUMMYFUNCTION("""COMPUTED_VALUE"""),360) -> 360 | D4: =IFERROR(__xludf.DUMMYFUNCTION("""COMPUTED_VALUE"""),270) -> 270 | E4: =IFERROR(__xludf.DUMMYFUNCTION("""COMPUTED_VALUE"""),7) -> 7 | F4: =IFERROR(__xludf.DUMMYFUNCTION("""COMPUTED_VALUE"""),861) -> 861
A5: =IFERROR(__xludf.DUMMYFUNCTION("""COMPUTED_VALUE"""),45661) -> 45661 | B5: =IFERROR(__xludf.DUMMYFUNCTION("""COMPUTED_VALUE"""),55742) -> 55742 | C5: =IFERROR(__xludf.DUMMYFUNCTION("""COMPUTED_VALUE"""),927) -> 927 | D5: =IFERROR(__xludf.DUMMYFUNCTION("""COMPUTED_VALUE"""),951) -> 951 | E5: =IFERROR(__xludf.DUMMYFUNCTION("""COMPUTED_VALUE"""),16) -> 16 | F5: =IFERROR(__xludf.DUMMYFUNCTION("""COMPUTED_VALUE"""),3532) -> 3532
A6: =IFERROR(__xludf.DUMMYFUNCTION("""COMPUTED_VALUE"""),45662) -> 45662 | B6: =IFERROR(__xludf.DUMMYFUNCTION("""COMPUTED_VALUE"""),50034) -> 50034 | C6: =IFERROR(__xludf.DUMMYFUNCTION("""COMPUTED_VALUE"""),669) -> 669 | D6: =IFERROR(__xludf.DUMMYFUNCTION("""COMPUTED_VALUE"""),588) -> 588 | E6: =IFERROR(__xludf.DUMMYFUNCTION("""COMPUTED_VALUE"""),15) -> 15 | F6: =IFERROR(__xludf.DUMMYFUNCTION("""COMPUTED_VALUE"""),3464) -> 3464
A7: =IFERROR(__xludf.DUMMYFUNCTION("""COMPUTED_VALUE"""),45663) -> 45663 | B7: =IFERROR(__xludf.DUMMYFUNCTION("""COMPUTED_VALUE"""),72795) -> 72795 | C7: =IFERROR(__xludf.DUMMYFUNCTION("""COMPUTED_VALUE"""),1327) -> 1327 | D7: =IFERROR(__xludf.DUMMYFUNCTION("""COMPUTED_VALUE"""),1464) -> 1464 | E7: =IFERROR(__xludf.DUMMYFUNCTION("""COMPUTED_VALUE"""),22) -> 22 | F7: =IFERROR(__xludf.DUMMYFUNCTION("""COMPUTED_VALUE"""),3804) -> 3804
A8: =IFERROR(__xludf.DUMMYFUNCTION("""COMPUTED_VALUE"""),45664) -> 45664 | B8: =IFERROR(__xludf.DUMMYFUNCTION("""COMPUTED_VALUE"""),54686) -> 54686 | C8: =IFERROR(__xludf.DUMMYFUNCTION("""COMPUTED_VALUE"""),1607) -> 1607 | D8: =IFERROR(__xludf.DUMMYFUNCTION("""COMPUTED_VALUE"""),1118) -> 1118 | E8: =IFERROR(__xludf.DUMMYFUNCTION("""COMPUTED_VALUE"""),33) -> 33 | F8: =IFERROR(__xludf.DUMMYFUNCTION("""COMPUTED_VALUE"""),6814) -> 6814
A9: =IFERROR(__xludf.DUMMYFUNCTION("""COMPUTED_VALUE"""),45665) -> 45665 | B9: =IFERROR(__xludf.DUMMYFUNCTION("""COMPUTED_VALUE"""),51903) -> 51903 | C9: =IFERROR(__xludf.DUMMYFUNCTION("""COMPUTED_VALUE"""),509) -> 509 | D9: =IFERROR(__xludf.DUMMYFUNCTION("""COMPUTED_VALUE"""),545) -> 545 | E9: =IFERROR(__xludf.DUMMYFUNCTION("""COMPUTED_VALUE"""),10) -> 10 | F9: =IFERROR(__xludf.DUMMYFUNCTION("""COMPUTED_VALUE"""),1671) -> 1671
A10: =IFERROR(__xludf.DUMMYFUNCTION("""COMPUTED_VALUE"""),45666) -> 45666 | B10: =IFERROR(__xludf.DUMMYFUNCTION("""COMPUTED_VALUE"""),96174) -> 96174 | C10: =IFERROR(__xludf.DUMMYFUNCTION("""COMPUTED_VALUE"""),2195) -> 2195 | D10: =IFERROR(__xludf.DUMMYFUNCTION("""COMPUTED_VALUE"""),1870) -> 1870 | E10: =IFERROR(__xludf.DUMMYFUNCTION("""COMPUTED_VALUE"""),38) -> 38 | F10: =IFERROR(__xludf.DUMMYFUNCTION("""COMPUTED_VALUE"""),8346) -> 8346
A11: =IFERROR(__xludf.DUMMYFUNCTION("""COMPUTED_VALUE"""),45667) -> 45667 | B11: =IFERROR(__xludf.DUMMYFUNCTION("""COMPUTED_VALUE"""),85203) -> 85203 | C11: =IFERROR(__xludf.DUMMYFUNCTION("""COMPUTED_VALUE"""),1569) -> 1569 | D11: =IFERROR(__xludf.DUMMYFUNCTION("""COMPUTED_VALUE"""),2066) -> 2066 | E11: =IFERROR(__xludf.DUMMYFUNCTION("""COMPUTED_VALUE"""),19) -> 19 | F11: =IFERROR(__xludf.DUMMYFUNCTION("""COMPUTED_VALUE"""),3876) -> 3876
A12: =IFERROR(__xludf.DUMMYFUNCTION("""COMPUTED_VALUE"""),45668) -> 45668 | B12: =IFERROR(__xludf.DUMMYFUNCTION("""COMPUTED_VALUE"""),81432) -> 81432 | C12: =IFERROR(__xludf.DUMMYFUNCTION("""COMPUTED_VALUE"""),1020) -> 1020 | D12: =IFERROR(__xludf.DUMMYFUNCTION("""COMPUTED_VALUE"""),1090) -> 1090 | E12: =IFERROR(__xludf.DUMMYFUNCTION("""COMPUTED_VALUE"""),20) -> 20 | F12: =IFERROR(__xludf.DUMMYFUNCTION("""COMPUTED_VALUE"""),4285) -> 4285
A13: =IFERROR(__xludf.DUMMYFUNCTION("""COMPUTED_VALUE"""),45669) -> 45669 | B13: =IFERROR(__xludf.DUMMYFUNCTION("""COMPUTED_VALUE"""),86724) -> 86724 | C13: =IFERROR(__xludf.DUMMYFUNCTION("""COMPUTED_VALUE"""),1608) -> 1608 | D13: =IFERROR(__xludf.DUMMYFUNCTION("""COMPUTED_VALUE"""),1626) -> 1626 | E13: =IFERROR(__xludf.DUMMYFUNCTION("""COMPUTED_VALUE"""),20) -> 20 | F13: =IFERROR(__xludf.DUMMYFUNCTION("""COMPUTED_VALUE"""),4266) -> 4266
A14: =IFERROR(__xludf.DUMMYFUNCTION("""COMPUTED_VALUE"""),45670) -> 45670 | B14: =IFERROR(__xludf.DUMMYFUNCTION("""COMPUTED_VALUE"""),97450) -> 97450 | C14: =IFERROR(__xludf.DUMMYFUNCTION("""COMPUTED_VALUE"""),2234) -> 2234 | D14: =IFERROR(__xludf.DUMMYFUNCTION("""COMPUTED_VALUE"""),1909) -> 1909 | E14: =IFERROR(__xludf.DUMMYFUNCTION("""COMPUTED_VALUE"""),32) -> 32 | F14: =IFERROR(__xludf.DUMMYFUNCTION("""COMPUTED_VALUE"""),4158) -> 4158
A15: =IFERROR(__xludf.DUMMYFUNCTION("""COMPUTED_VALUE"""),45671) -> 45671 | B15: =IFERROR(__xludf.DUMMYFUNCTION("""COMPUTED_VALUE"""),87059) -> 87059 | C15: =IFERROR(__xludf.DUMMYFUNCTION("""COMPUTED_VALUE"""),1682) -> 1682 | D15: =IFERROR(__xludf.DUMMYFUNCTION("""COMPUTED_VALUE"""),1782) -> 1782 | E15: =IFERROR(__xludf.DUMMYFUNCTION("""COMPUTED_VALUE"""),31) -> 31 | F15: =IFERROR(__xludf.DUMMYFUNCTION("""COMPUTED_VALUE"""),4794) -> 4794
A16: =IFERROR(__xludf.DUMMYFUNCTION("""COMPUTED_VALUE"""),45672) -> 45672 | B16: =IFERROR(__xludf.DUMMYFUNCTION("""COMPUTED_VALUE"""),82315) -> 82315 | C16: =IFERROR(__xludf.DUMMYFUNCTION("""COMPUTED_VALUE"""),2176) -> 2176 | D16: =IFERROR(__xludf.DUMMYFUNCTION("""COMPUTED_VALUE"""),1913) -> 1913 | E16: =IFERROR(__xludf.DUMMYFUNCTION("""COMPUTED_VALUE"""),34) -> 34 | F16: =IFERROR(__xludf.DUMMYFUNCTION("""COMPUTED_VALUE"""),3083) -> 3083
A17: =IFERROR(__xludf.DUMMYFUNCTION("""COMPUTED_VALUE"""),45673) -> 45673 | B17: =IFERROR(__xludf.DUMMYFUNCTION("""COMPUTED_VALUE"""),30991) -> 30991 | C17: =IFERROR(__xludf.DUMMYFUNCTION("""COMPUTED_VALUE"""),726) -> 726 | D17: =IFERROR(__xludf.DUMMYFUNCTION("""COMPUTED_VALUE"""),984) -> 984 | E17: =IFERROR(__xludf.DUMMYFUNCTION("""COMPUTED_VALUE"""),13) -> 13 | F17: =IFERROR(__xludf.DUMMYFUNCTION("""COMPUTED_VALUE"""),1970) -> 1970
A18: =IFERROR(__xludf.DUMMYFUNCTION("""COMPUTED_VALUE"""),45674) -> 45674 | B18: =IFERROR(__xludf.DUMMYFUNCTION("""COMPUTED_VALUE"""),112741) -> 112741 | C18: =IFERROR(__xludf.DUMMYFUNCTION("""COMPUTED_VALUE"""),2898) -> 2898 | D18: =IFERROR(__xludf.DUMMYFUNCTION("""COMPUTED_VALUE"""),2966) -> 2966 | E18: =IFERROR(__xludf.DUMMYFUNCTION("""COMPUTED_VALUE"""),70) -> 70 | F18: =IFERROR(__xludf.DUMMYFUNCTION("""COMPUTED_VALUE"""),10287) -> 10287
A19: =IFERROR(__xludf.DUMMYFUNCTION("""COMPUTED_VALUE"""),45675) -> 45675 | B19: =IFERROR(__xludf.DUMMYFUNCTION("""COMPUTED_VALUE"""),65598) -> 65598 | C19: =IFERROR(__xludf.DUMMYFUNCTION("""COMPUTED_VALUE"""),2140) -> 2140 | D19: =IFERROR(__xludf.DUMMYFUNCTION("""COMPUTED_VALUE"""),1439) -> 1439 | E19: =IFERROR(__xludf.DUMMYFUNCTION("""COMPUTED_VALUE"""),28) -> 28 | F19: =IFERROR(__xludf.DUMMYFUNCTION("""COMPUTED_VALUE"""),3779) -> 3779
A20: =IFERROR(__xludf.DUMMYFUNCTION("""COMPUTED_VALUE"""),45676) -> 45676 | B20: =IFERROR(__xludf.DUMMYFUNCTION("""COMPUTED_VALUE"""),74983) -> 74983 | C20: =IFERROR(__xludf.DUMMYFUNCTION("""COMPUTED_VALUE"""),1011) -> 1011 | D20: =IFERROR(__xludf.DUMMYFUNCTION("""COMPUTED_VALUE"""),1029) -> 1029 | E20: =IFERROR(__xludf.DUMMYFUNCTION("""COMPUTED_VALUE"""),23) -> 23 | F20: =IFERROR(__xludf.DUMMYFUNCTION("""COMPUTED_VALUE"""),2972) -> 2972
A21: =IFERROR(__xludf.DUMMYFUNCTION("""COMPUTED_VALUE"""),45677) -> 45677 | B21: =IFERROR(__xludf.DUMMYFUNCTION("""COMPUTED_VALUE"""),89780) -> 89780 | C21: =IFERROR(__xludf.DUMMYFUNCTION("""COMPUTED_VALUE"""),1406) -> 1406 | D21: =IFERROR(__xludf.DUMMYFUNCTION("""COMPUTED_VALUE"""),998) -> 998 | E21: =IFERROR(__xludf.DUMMYFUNCTION("""COMPUTED_VALUE"""),18) -> 18 | F21: =IFERROR(__xludf.DUMMYFUNCTION("""COMPUTED_VALUE"""),4343) -> 4343
A22: =IFERROR(__xludf.DUMMYFUNCTION("""COMPUTED_VALUE"""),45678) -> 45678 | B22: =IFERROR(__xludf.DUMMYFUNCTION("""COMPUTED_VALUE"""),79638) -> 79638 | C22: =IFERROR(__xludf.DUMMYFUNCTION("""COMPUTED_VALUE"""),1829) -> 1829 | D22: =IFERROR(__xludf.DUMMYFUNCTION("""COMPUTED_VALUE"""),1825) -> 1825 | E22: =IFERROR(__xludf.DUMMYFUNCTION("""COMPUTED_VALUE"""),30) -> 30 | F22: =IFERROR(__xludf.DUMMYFUNCTION("""COMPUTED_VALUE"""),4958) -> 4958
A23: =IFERROR(__xludf.DUMMYFUNCTION("""COMPUTED_VALUE"""),45679) -> 45679 | B23: =IFERROR(__xludf.DUMMYFUNCTION("""COMPUTED_VALUE"""),56982) -> 56982 | C23: =IFERROR(__xludf.DUMMYFUNCTION("""COMPUTED_VALUE"""),596) -> 596 | D23: =IFERROR(__xludf.DUMMYFUNCTION("""COMPUTED_VALUE"""),603) -> 603 | E23: =IFERROR(__xludf.DUMMYFUNCTION("""COMPUTED_VALUE"""),11) -> 11 | F23: =IFERROR(__xludf.DUMMYFUNCTION("""COMPUTED_VALUE"""),1558) -> 1558
A24: =IFERROR(__xludf.DUMMYFUNCTION("""COMPUTED_VALUE"""),45680) -> 45680 | B24: =IFERROR(__xludf.DUMMYFUNCTION("""COMPUTED_VALUE"""),25416) -> 25416 | C24: =IFERROR(__xludf.DUMMYFUNCTION("""COMPUTED_VALUE"""),196) -> 196 | D24: =IFERROR(__xludf.DUMMYFUNCTION("""COMPUTED_VALUE"""),129) -> 129 | E24: =IFERROR(__xludf.DUMMYFUNCTION("""COMPUTED_VALUE"""),3) -> 3 | F24: =IFERROR(__xludf.DUMMYFUNCTION("""COMPUTED_VALUE"""),693) -> 693
A25: =IFERROR(__xludf.DUMMYFUNCTION("""COMPUTED_VALUE"""),45681) -> 45681 | B25: =IFERROR(__xludf.DUMMYFUNCTION("""COMPUTED_VALUE"""),83714) -> 83714 | C25: =IFERROR(__xludf.DUMMYFUNCTION("""COMPUTED_VALUE"""),1288) -> 1288 | D25: =IFERROR(__xludf.DUMMYFUNCTION("""COMPUTED_VALUE"""),1499) -> 1499 | E25: =IFERROR(__xludf.DUMMYFUNCTION("""COMPUTED_VALUE"""),29) -> 29 | F25: =IFERROR(__xludf.DUMMYFUNCTION("""COMPUTED_VALUE"""),5466) -> 5466
A26: =IFERROR(__xludf.DUMMYFUNCTION("""COMPUTED_VALUE"""),45682) -> 45682 | B26: =IFERROR(__xludf.DUMMYFUNCTION("""COMPUTED_VALUE"""),61918) -> 61918 | C26: =IFERROR(__xludf.DUMMYFUNCTION("""COMPUTED_VALUE"""),1513) -> 1513 | D26: =IFERROR(__xludf.DUMMYFUNCTION("""COMPUTED_VALUE"""),2129) -> 2129 | E26: =IFERROR(__xludf.DUMMYFUNCTION("""COMPUTED_VALUE"""),35) -> 35 | F26: =IFERROR(__xludf.DUMMYFUNCTION("""COMPUTED_VALUE"""),6437) -> 6437
A27: =IFERROR(__xludf.DUMMYFUNCTION("""COMPUTED_VALUE"""),45683) -> 45683 | B27: =IFERROR(__xludf.DUMMYFUNCTION("""COMPUTED_VALUE"""),39505) -> 39505 | C27: =IFERROR(__xludf.DUMMYFUNCTION("""COMPUTED_VALUE"""),399) -> 399 | D27: =IFERROR(__xludf.DUMMYFUNCTION("""COMPUTED_VALUE"""),454) -> 454 | E27: =IFERROR(__xludf.DUMMYFUNCTION("""COMPUTED_VALUE"""),7) -> 7 | F27: =IFERROR(__xludf.DUMMYFUNCTION("""COMPUTED_VALUE"""),1114) -> 1114
A28: =IFERROR(__xludf.DUMMYFUNCTION("""COMPUTED_VALUE"""),45684) -> 45684 | B28: =IFERROR(__xludf.DUMMYFUNCTION("""COMPUTED_VALUE"""),35645) -> 35645 | C28: =IFERROR(__xludf.DUMMYFUNCTION("""COMPUTED_VALUE"""),443) -> 443 | D28: =IFERROR(__xludf.DUMMYFUNCTION("""COMPUTED_VALUE"""),593) -> 593 | E28: =IFERROR(__xludf.DUMMYFUNCTION("""COMPUTED_VALUE"""),8) -> 8 | F28: =IFERROR(__xludf.DUMMYFUNCTION("""COMPUTED_VALUE"""),1750) -> 1750
A29: =IFERROR(__xludf.DUMMYFUNCTION("""COMPUTED_VALUE"""),45685) -> 45685 | B29: =IFERROR(__xludf.DUMMYFUNCTION("""COMPUTED_VALUE"""),77867) -> 77867 | C29: =IFERROR(__xludf.DUMMYFUNCTION("""COMPUTED_VALUE"""),981) -> 981 | D29: =IFERROR(__xludf.DUMMYFUNCTION("""COMPUTED_VALUE"""),1055) -> 1055 | E29: =IFERROR(__xludf.DUMMYFUNCTION("""COMPUTED_VALUE"""),23) -> 23 | F29: =IFERROR(__xludf.DUMMYFUNCTION("""COMPUTED_VALUE"""),4255) -> 4255
A30: =IFERROR(__xludf.DUMMYFUNCTION("""COMPUTED_VALUE"""),45686) -> 45686 | B30: =IFERROR(__xludf.DUMMYFUNCTION("""COMPUTED_VALUE"""),40913) -> 40913 | C30: =IFERROR(__xludf.DUMMYFUNCTION("""COMPUTED_VALUE"""),929) -> 929 | D30: =IFERROR(__xludf.DUMMYFUNCTION("""COMPUTED_VALUE"""),669) -> 669 | E30: =IFERROR(__xludf.DUMMYFUNCTION("""COMPUTED_VALUE"""),17) -> 17 | F30: =IFERROR(__xludf.DUMMYFUNCTION("""COMPUTED_VALUE"""),3399) -> 3399
A31: =IFERROR(__xludf.DUMMYFUNCTION("""COMPUTED_VALUE"""),45687) -> 45687 | B31: =IFERROR(__xludf.DUMMYFUNCTION("""COMPUTED_VALUE"""),64428) -> 64428 | C31: =IFERROR(__xludf.DUMMYFUNCTION("""COMPUTED_VALUE"""),2025) -> 2025 | D31: =IFERROR(__xludf.DUMMYFUNCTION("""COMPUTED_VALUE"""),1969) -> 1969 | E31: =IFERROR(__xludf.DUMMYFUNCTION("""COMPUTED_VALUE"""),30) -> 30 | F31: =IFERROR(__xludf.DUMMYFUNCTION("""COMPUTED_VALUE"""),4442) -> 4442
A32: =IFERROR(__xludf.DUMMYFUNCTION("""COMPUTED_VALUE"""),45688) -> 45688 | B32: =IFERROR(__xludf.DUMMYFUNCTION("""COMPUTED_VALUE"""),93925) -> 93925 | C32: =IFERROR(__xludf.DUMMYFUNCTION("""COMPUTED_VALUE"""),1932) -> 1932 | D32: =IFERROR(__xludf.DUMMYFUNCTION("""COMPUTED_VALUE"""),2165) -> 2165 | E32: =IFERROR(__xludf.DUMMYFUNCTION("""COMPUTED_VALUE"""),36) -> 36 | F32: =IFERROR(__xludf.DUMMYFUNCTION("""COMPUTED_VALUE"""),6059) -> 6059
A33: =IFERROR(__xludf.DUMMYFUNCTION("""COMPUTED_VALUE"""),45689) -> 45689 | B33: =IFERROR(__xludf.DUMMYFUNCTION("""COMPUTED_VALUE"""),115794) -> 115794 | C33: =IFERROR(__xludf.DUMMYFUNCTION("""COMPUTED_VALUE"""),3255) -> 3255 | D33: =IFERROR(__xludf.DUMMYFUNCTION("""COMPUTED_VALUE"""),2584) -> 2584 | E33: =IFERROR(__xludf.DUMMYFUNCTION("""COMPUTED_VALUE"""),61) -> 61 | F33: =IFERROR(__xludf.DUMMYFUNCTION("""COMPUTED_VALUE"""),9359) -> 9359
A34: =IFERROR(__xludf.DUMMYFUNCTION("""COMPUTED_VALUE"""),45690) -> 45690 | B34: =IFERROR(__xludf.DUMMYFUNCTION("""COMPUTED_VALUE"""),39694) -> 39694 | C34: =IFERROR(__xludf.DUMMYFUNCTION("""COMPUTED_VALUE"""),514) -> 514 | D34: =IFERROR(__xludf.DUMMYFUNCTION("""COMPUTED_VALUE"""),662) -> 662 | E34: =IFERROR(__xludf.DUMMYFUNCTION("""COMPUTED_VALUE"""),9) -> 9 | F34: =IFERROR(__xludf.DUMMYFUNCTION("""COMPUTED_VALUE"""),2087) -> 2087
A35: =IFERROR(__xludf.DUMMYFUNCTION("""COMPUTED_VALUE"""),45691) -> 45691 | B35: =IFERROR(__xludf.DUMMYFUNCTION("""COMPUTED_VALUE"""),37397) -> 37397 | C35: =IFERROR(__xludf.DUMMYFUNCTION("""COMPUTED_VALUE"""),807) -> 807 | D35: =IFERROR(__xludf.DUMMYFUNCTION("""COMPUTED_VALUE"""),629) -> 629 | E35: =IFERROR(__xludf.DUMMYFUNCTION("""COMPUTED_VALUE"""),17) -> 17 | F35: =IFERROR(__xludf.DUMMYFUNCTION("""COMPUTED_VALUE"""),2780) -> 2780
A36: =IFERROR(__xludf.DUMMYFUNCTION("""COMPUTED_VALUE"""),45692) -> 45692 | B36: =IFERROR(__xludf.DUMMYFUNCTION("""COMPUTED_VALUE"""),23589) -> 23589 | C36: =IFERROR(__xludf.DUMMYFUNCTION("""COMPUTED_VALUE"""),480) -> 480 | D36: =IFERROR(__xludf.DUMMYFUNCTION("""COMPUTED_VALUE"""),401) -> 401 | E36: =IFERROR(__xludf.DUMMYFUNCTION("""COMPUTED_VALUE"""),8) -> 8 | F36: =IFERROR(__xludf.DUMMYFUNCTION("""COMPUTED_VALUE"""),1138) -> 1138
A37: =IFERROR(__xludf.DUMMYFUNCTION("""COMPUTED_VALUE"""),45693) -> 45693 | B37: =IFERROR(__xludf.DUMMYFUNCTION("""COMPUTED_VALUE"""),92100) -> 92100 | C37: =IFERROR(__xludf.DUMMYFUNCTION("""COMPUTED_VALUE"""),2462) -> 2462 | D37: =IFERROR(__xludf.DUMMYFUNCTION("""COMPUTED_VALUE"""),2909) -> 2909 | E37: =IFERROR(__xludf.DUMMYFUNCTION("""COMPUTED_VALUE"""),43) -> 43 | F37: =IFERROR(__xludf.DUMMYFUNCTION("""COMPUTED_VALUE"""),8356) -> 8356
A38: =IFERROR(__xludf.DUMMYFUNCTION("""COMPUTED_VALUE"""),45694) -> 45694 | B38: =IFERROR(__xludf.DUMMYFUNCTION("""COMPUTED_VALUE"""),93317) -> 93317 | C38: =IFERROR(__xludf.DUMMYFUNCTION("""COMPUTED_VALUE"""),1307) -> 1307 | D38: =IFERROR(__xludf.DUMMYFUNCTION("""COMPUTED_VALUE"""),1032) -> 1032 | E38: =IFERROR(__xludf.DUMMYFUNCTION("""COMPUTED_VALUE"""),23) -> 23 | F38: =IFERROR(__xludf.DUMMYFUNCTION("""COMPUTED_VALUE"""),3098) -> 3098
A39: =IFERROR(__xludf.DUMMYFUNCTION("""COMPUTED_VALUE"""),45695) -> 45695 | B39: =IFERROR(__xludf.DUMMYFUNCTION("""COMPUTED_VALUE"""),105397) -> 105397 | C39: =IFERROR(__xludf.DUMMYFUNCTION("""COMPUTED_VALUE"""),2964) -> 2964 | D39: =IFERROR(__xludf.DUMMYFUNCTION("""COMPUTED_VALUE"""),2764) -> 2764 | E39: =IFERROR(__xludf.DUMMYFUNCTION("""COMPUTED_VALUE"""),50) -> 50 | F39: =IFERROR(__xludf.DUMMYFUNCTION("""COMPUTED_VALUE"""),7707) -> 7707
A40: =IFERROR(__xludf.DUMMYFUNCTION("""COMPUTED_VALUE"""),45696) -> 45696 | B40: =IFERROR(__xludf.DUMMYFUNCTION("""COMPUTED_VALUE"""),83825) -> 83825 | C40: =IFERROR(__xludf.DUMMYFUNCTION("""COMPUTED_VALUE"""),1171) -> 1171 | D40: =IFERROR(__xludf.DUMMYFUNCTION("""COMPUTED_VALUE"""),821) -> 821 | E40: =IFERROR(__xludf.DUMMYFUNCTION("""COMPUTED_VALUE"""),21) -> 21 | F40: =IFERROR(__xludf.DUMMYFUNCTION("""COMPUTED_VALUE"""),3938) -> 3938
...

Sheet Instagram Ads Performance Metri
A1: Date | B1: Month | C1: Impressions | D1: CTR | E1: Clicks | F1: CPC | G1: CPM | H1: Spend | I1: Conversion rate | J1: Conversions | K1: Avg. conversion value | L1: Revenue | M1: ROAS | N1: CPA
A2: ='Instagram Ads Raw Data'!A2 -> 45658 | B2: =MONTH(A2) -> 1 | C2: ='Instagram Ads Raw Data'!B2 -> 27382 | D2: =E2/C2 -> 0.017639325 | E2: ='Instagram Ads Raw Data'!C2 -> 483 | F2: =H2/E2 -> 1.3374741 | G2: =H2/(C2/1000) -> 23.592141 | H2: ='Instagram Ads Raw Data'!D2 -> 646 | I2: =J2/E2 -> 0.016563147 | J2: ='Instagram Ads Raw Data'!E2 -> 8 | K2: =L2/J2 -> 171.875 | L2: ='Instagram Ads Raw Data'!F2 -> 1375 | M2: =L2/H2 -> 2.128483 | N2: =H2/J2 -> 80.75
A3: ='Instagram Ads Raw Data'!A3 -> 45659 | B3: =MONTH(A3) -> 1 | C3: ='Instagram Ads Raw Data'!B3 -> 99168 | D3: =E3/C3 -> 0.015740965 | E3: ='Instagram Ads Raw Data'!C3 -> 1561 | F3: =H3/E3 -> 1.4445868 | G3: =H3/(C3/1000) -> 22.73919 | H3: ='Instagram Ads Raw Data'!D3 -> 2255 | I3: =J3/E3 -> 0.022421525 | J3: ='Instagram Ads Raw Data'!E3 -> 35 | K3: =L3/J3 -> 147.4 | L3: ='Instagram Ads Raw Data'!F3 -> 5159 | M3: =L3/H3 -> 2.2878049 | N3: =H3/J3 -> 64.428571
A4: ='Instagram Ads Raw Data'!A4 -> 45660 | B4: =MONTH(A4) -> 1 | C4: ='Instagram Ads Raw Data'!B4 -> 14891 | D4: =E4/C4 -> 0.018333221 | E4: ='Instagram Ads Raw Data'!C4 -> 273 | F4: =H4/E4 -> 1.1391941 | G4: =H4/(C4/1000) -> 20.885098 | H4: ='Instagram Ads Raw Data'!D4 -> 311 | I4: =J4/E4 -> 0.021978022 | J4: ='Instagram Ads Raw Data'!E4 -> 6 | K4: =L4/J4 -> 119.5 | L4: ='Instagram Ads Raw Data'!F4 -> 717 | M4: =L4/H4 -> 2.3054662 | N4: =H4/J4 -> 51.833333
A5: ='Instagram Ads Raw Data'!A5 -> 45661 | B5: =MONTH(A5) -> 1 | C5: ='Instagram Ads Raw Data'!B5 -> 42989 | D5: =E5/C5 -> 0.015864523 | E5: ='Instagram Ads Raw Data'!C5 -> 682 | F5: =H5/E5 -> 1.7478006 | G5: =H5/(C5/1000) -> 27.728023 | H5: ='Instagram Ads Raw Data'!D5 -> 1192 | I5: =J5/E5 -> 0.019061584 | J5: ='Instagram Ads Raw Data'!E5 -> 13 | K5: =L5/J5 -> 228.38462 | L5: ='Instagram Ads Raw Data'!F5 -> 2969 | M5: =L5/H5 -> 2.4907718 | N5: =H5/J5 -> 91.692308
A6: ='Instagram Ads Raw Data'!A6 -> 45662 | B6: =MONTH(A6) -> 1 | C6: ='Instagram Ads Raw Data'!B6 -> 36381 | D6: =E6/C6 -> 0.015365163 | E6: ='Instagram Ads Raw Data'!C6 -> 559 | F6: =H6/E6 -> 1.4025045 | G6: =H6/(C6/1000) -> 21.54971 | H6: ='Instagram Ads Raw Data'!D6 -> 784 | I6: =J6/E6 -> 0.023255814 | J6: ='Instagram Ads Raw Data'!E6 -> 13 | K6: =L6/J6 -> 196.61538 | L6: ='Instagram Ads Raw Data'!F6 -> 2556 | M6: =L6/H6 -> 3.2602041 | N6: =H6/J6 -> 60.307692
A7: ='Instagram Ads Raw Data'!A7 -> 45663 | B7: =MONTH(A7) -> 1 | C7: ='Instagram Ads Raw Data'!B7 -> 56836 | D7: =E7/C7 -> 0.019864171 | E7: ='Instagram Ads Raw Data'!C7 -> 1129 | F7: =H7/E7 -> 1.7847653 | G7: =H7/(C7/1000) -> 35.452882 | H7: ='Instagram Ads Raw Data'!D7 -> 2015 | I7: =J7/E7 -> 0.014171833 | J7: ='Instagram Ads Raw Data'!E7 -> 16 | K7: =L7/J7 -> 168.5625 | L7: ='Instagram Ads Raw Data'!F7 -> 2697 | M7: =L7/H7 -> 1.3384615 | N7: =H7/J7 -> 125.9375
A8: ='Instagram Ads Raw Data'!A8 -> 45664 | B8: =MONTH(A8) -> 1 | C8: ='Instagram Ads Raw Data'!B8 -> 45926 | D8: =E8/C8 -> 0.024931411 | E8: ='Instagram Ads Raw Data'!C8 -> 1145 | F8: =H8/E8 -> 1.0637555 | G8: =H8/(C8/1000) -> 26.520925 | H8: ='Instagram Ads Raw Data'!D8 -> 1218 | I8: =J8/E8 -> 0.024454148 | J8: ='Instagram Ads Raw Data'!E8 -> 28 | K8: =L8/J8 -> 198.17857 | L8: ='Instagram Ads Raw Data'!F8 -> 5549 | M8: =L8/H8 -> 4.5558292 | N8: =H8/J8 -> 43.5
A9: ='Instagram Ads Raw Data'!A9 -> 45665 | B9: =MONTH(A9) -> 1 | C9: ='Instagram Ads Raw Data'!B9 -> 43071 | D9: =E9/C9 -> 0.0082654222 | E9: ='Instagram Ads Raw Data'!C9 -> 356 | F9: =H9/E9 -> 1.6910112 | G9: =H9/(C9/1000) -> 13.976922 | H9: ='Instagram Ads Raw Data'!D9 -> 602 | I9: =J9/E9 -> 0.025280899 | J9: ='Instagram Ads Raw Data'!E9 -> 9 | K9: =L9/J9 -> 155 | L9: ='Instagram Ads Raw Data'!F9 -> 1395 | M9: =L9/H9 -> 2.3172757 | N9: =H9/J9 -> 66.888889
A10: ='Instagram Ads Raw Data'!A10 -> 45666 | B10: =MONTH(A10) -> 1 | C10: ='Instagram Ads Raw Data'!B10 -> 82343 | D10: =E10/C10 -> 0.022673451 | E10: ='Instagram Ads Raw Data'!C10 -> 1867 | F10: =H10/E10 -> 1.2581682 | G10: =H10/(C10/1000) -> 28.527015 | H10: ='Instagram Ads Raw Data'!D10 -> 2349 | I10: =J10/E10 -> 0.016068559 | J10: ='Instagram Ads Raw Data'!E10 -> 30 | K10: =L10/J10 -> 194.5 | L10: ='Instagram Ads Raw Data'!F10 -> 5835 | M10: =L10/H10 -> 2.4840358 | N10: =H10/J10 -> 78.3
A11: ='Instagram Ads Raw Data'!A11 -> 45667 | B11: =MONTH(A11) -> 1 | C11: ='Instagram Ads Raw Data'!B11 -> 76027 | D11: =E11/C11 -> 0.016428374 | E11: ='Instagram Ads Raw Data'!C11 -> 1249 | F11: =H11/E11 -> 1.9343475 | G11: =H11/(C11/1000) -> 31.778184 | H11: ='Instagram Ads Raw Data'!D11 -> 2416 | I11: =J11/E11 -> 0.012810248 | J11: ='Instagram Ads Raw Data'!E11 -> 16 | K11: =L11/J11 -> 192.8125 | L11: ='Instagram Ads Raw Data'!F11 -> 3085 | M11: =L11/H11 -> 1.276904 | N11: =H11/J11 -> 151
A12: ='Instagram Ads Raw Data'!A12 -> 45668 | B12: =MONTH(A12) -> 1 | C12: ='Instagram Ads Raw Data'!B12 -> 80956 | D12: =E12/C12 -> 0.0090543011 | E12: ='Instagram Ads Raw Data'!C12 -> 733 | F12: =H12/E12 -> 1.744884 | G12: =H12/(C12/1000) -> 15.798705 | H12: ='Instagram Ads Raw Data'!D12 -> 1279 | I12: =J12/E12 -> 0.024556617 | J12: ='Instagram Ads Raw Data'!E12 -> 18 | K12: =L12/J12 -> 161.77778 | L12: ='Instagram Ads Raw Data'!F12 -> 2912 | M12: =L12/H12 -> 2.2767787 | N12: =H12/J12 -> 71.055556
A13: ='Instagram Ads Raw Data'!A13 -> 45669 | B13: =MONTH(A13) -> 1 | C13: ='Instagram Ads Raw Data'!B13 -> 68072 | D13: =E13/C13 -> 0.019567517 | E13: ='Instagram Ads Raw Data'!C13 -> 1332 | F13: =H13/E13 -> 1.777027 | G13: =H13/(C13/1000) -> 34.772006 | H13: ='Instagram Ads Raw Data'!D13 -> 2367 | I13: =J13/E13 -> 0.011261261 | J13: ='Instagram Ads Raw Data'!E13 -> 15 | K13: =L13/J13 -> 215.6 | L13: ='Instagram Ads Raw Data'!F13 -> 3234 | M13: =L13/H13 -> 1.3662864 | N13: =H13/J13 -> 157.8
... A366: ='Instagram Ads Raw Data'!A366 -> 46022 | B366: =MONTH(A366) -> 12 | C366: ='Instagram Ads Raw Data'!B366 -> 83988 | D366: =E366/C366 -> 0.025991808 | E366: ='Instagram Ads Raw Data'!C366 -> 2183 | F366: =H366/E366 -> 1.0164911 | G366: =H366/(C366/1000) -> 26.420441 | H366: ='Instagram Ads Raw Data'!D366 -> 2219 | I366: =J366/E366 -> 0.018781493 | J366: ='Instagram Ads Raw Data'!E366 -> 41 | K366: =L366/J366 -> 145.09756 | L366: ='Instagram Ads Raw Data'!F366 -> 5949 | M366: =L366/H366 -> 2.6809374 | N366: =H366/J366 -> 54.121951
F373: {=_xludf.XLOOKUP(MAX(L2:L366), L2:L366, B2:B366)} -> #NAME?

Sheet Tiktok Ads Performance Metrics
A1: Date | B1: Month | C1: Impressions | D1: CTR | E1: Clicks | F1: CPC | G1: CPM | H1: Spend | I1: Conversion rate | J1: Conversions | K1: Avg. conversion value | L1: Revenue
A2: ='TikTok Ads Raw Data'!A2 -> 45658 | B2: =MONTH(A:A) -> 1 | C2: ='TikTok Ads Raw Data'!B2 -> 37761 | D2: =E2/C2 -> 0.018140409 | E2: ='TikTok Ads Raw Data'!C2 -> 685 | F2: =H2/E2 -> 0.75766423 | G2: =H2/(C2/1000) -> 13.744339 | H2: ='TikTok Ads Raw Data'!D2 -> 519 | I2: =J2/E2 -> 0.016058394 | J2: ='TikTok Ads Raw Data'!E2 -> 11 | K2: =L2/J2 -> 155.54545 | L2: ='TikTok Ads Raw Data'!F2 -> 1711
A3: ='TikTok Ads Raw Data'!A3 -> 45659 | B3: =MONTH(A:A) -> 1 | C3: ='TikTok Ads Raw Data'!B3 -> 113622 | D3: =E3/C3 -> 0.01882558 | E3: ='TikTok Ads Raw Data'!C3 -> 2139 | F3: =H3/E3 -> 0.89901823 | G3: =H3/(C3/1000) -> 16.924539 | H3: ='TikTok Ads Raw Data'!D3 -> 1923 | I3: =J3/E3 -> 0.023375409 | J3: ='TikTok Ads Raw Data'!E3 -> 50 | K3: =L3/J3 -> 125.24 | L3: ='TikTok Ads Raw Data'!F3 -> 6262
A4: ='TikTok Ads Raw Data'!A4 -> 45660 | B4: =MONTH(A:A) -> 1 | C4: ='TikTok Ads Raw Data'!B4 -> 25676 | D4: =E4/C4 -> 0.014020876 | E4: ='TikTok Ads Raw Data'!C4 -> 360 | F4: =H4/E4 -> 0.75 | G4: =H4/(C4/1000) -> 10.515657 | H4: ='TikTok Ads Raw Data'!D4 -> 270 | I4: =J4/E4 -> 0.019444444 | J4: ='TikTok Ads Raw Data'!E4 -> 7 | K4: =L4/J4 -> 123 | L4: ='TikTok Ads Raw Data'!F4 -> 861
A5: ='TikTok Ads Raw Data'!A5 -> 45661 | B5: =MONTH(A:A) -> 1 | C5: ='TikTok Ads Raw Data'!B5 -> 55742 | D5: =E5/C5 -> 0.016630189 | E5: ='TikTok Ads Raw Data'!C5 -> 927 | F5: =H5/E5 -> 1.02589 | G5: =H5/(C5/1000) -> 17.060744 | H5: ='TikTok Ads Raw Data'!D5 -> 951 | I5: =J5/E5 -> 0.017259978 | J5: ='TikTok Ads Raw Data'!E5 -> 16 | K5: =L5/J5 -> 220.75 | L5: ='TikTok Ads Raw Data'!F5 -> 3532
A6: ='TikTok Ads Raw Data'!A6 -> 45662 | B6: =MONTH(A:A) -> 1 | C6: ='TikTok Ads Raw Data'!B6 -> 50034 | D6: =E6/C6 -> 0.013370908 | E6: ='TikTok Ads Raw Data'!C6 -> 669 | F6: =H6/E6 -> 0.87892377 | G6: =H6/(C6/1000) -> 11.752009 | H6: ='TikTok Ads Raw Data'!D6 -> 588 | I6: =J6/E6 -> 0.022421525 | J6: ='TikTok Ads Raw Data'!E6 -> 15 | K6: =L6/J6 -> 230.93333 | L6: ='TikTok Ads Raw Data'!F6 -> 3464
A7: ='TikTok Ads Raw Data'!A7 -> 45663 | B7: =MONTH(A:A) -> 1 | C7: ='TikTok Ads Raw Data'!B7 -> 72795 | D7: =E7/C7 -> 0.018229274 | E7: ='TikTok Ads Raw Data'!C7 -> 1327 | F7: =H7/E7 -> 1.1032404 | G7: =H7/(C7/1000) -> 20.111271 | H7: ='TikTok Ads Raw Data'!D7 -> 1464 | I7: =J7/E7 -> 0.016578749 | J7: ='TikTok Ads Raw Data'!E7 -> 22 | K7: =L7/J7 -> 172.90909 | L7: ='TikTok Ads Raw Data'!F7 -> 3804
A8: ='TikTok Ads Raw Data'!A8 -> 45664 | B8: =MONTH(A:A) -> 1 | C8: ='TikTok Ads Raw Data'!B8 -> 54686 | D8: =E8/C8 -> 0.029385949 | E8: ='TikTok Ads Raw Data'!C8 -> 1607 | F8: =H8/E8 -> 0.69570629 | G8: =H8/(C8/1000) -> 20.443989 | H8: ='TikTok Ads Raw Data'!D8 -> 1118 | I8: =J8/E8 -> 0.020535159 | J8: ='TikTok Ads Raw Data'!E8 -> 33 | K8: =L8/J8 -> 206.48485 | L8: ='TikTok Ads Raw Data'!F8 -> 6814
A9: ='TikTok Ads Raw Data'!A9 -> 45665 | B9: =MONTH(A:A) -> 1 | C9: ='TikTok Ads Raw Data'!B9 -> 51903 | D9: =E9/C9 -> 0.0098067549 | E9: ='TikTok Ads Raw Data'!C9 -> 509 | F9: =H9/E9 -> 1.0707269 | G9: =H9/(C9/1000) -> 10.500356 | H9: ='TikTok Ads Raw Data'!D9 -> 545 | I9: =J9/E9 -> 0.019646365 | J9: ='TikTok Ads Raw Data'!E9 -> 10 | K9: =L9/J9 -> 167.1 | L9: ='TikTok Ads Raw Data'!F9 -> 1671
A10: ='TikTok Ads Raw Data'!A10 -> 45666 | B10: =MONTH(A:A) -> 1 | C10: ='TikTok Ads Raw Data'!B10 -> 96174 | D10: =E10/C10 -> 0.022823216 | E10: ='TikTok Ads Raw Data'!C10 -> 2195 | F10: =H10/E10 -> 0.85193622 | G10: =H10/(C10/1000) -> 19.443925 | H10: ='TikTok Ads Raw Data'!D10 -> 1870 | I10: =J10/E10 -> 0.017312073 | J10: ='TikTok Ads Raw Data'!E10 -> 38 | K10: =L10/J10 -> 219.63158 | L10: ='TikTok Ads Raw Data'!F10 -> 8346
A11: ='TikTok Ads Raw Data'!A11 -> 45667 | B11: =MONTH(A:A) -> 1 | C11: ='TikTok Ads Raw Data'!B11 -> 85203 | D11: =E11/C11 -> 0.018414845 | E11: ='TikTok Ads Raw Data'!C11 -> 1569 | F11: =H11/E11 -> 1.3167623 | G11: =H11/(C11/1000) -> 24.247972 | H11: ='TikTok Ads Raw Data'!D11 -> 2066 | I11: =J11/E11 -> 0.012109624 | J11: ='TikTok Ads Raw Data'!E11 -> 19 | K11: =L11/J11 -> 204 | L11: ='TikTok Ads Raw Data'!F11 -> 3876
A12: ='TikTok Ads Raw Data'!A12 -> 45668 | B12: =MONTH(A:A) -> 1 | C12: ='TikTok Ads Raw Data'!B12 -> 81432 | D12: =E12/C12 -> 0.012525788 | E12: ='TikTok Ads Raw Data'!C12 -> 1020 | F12: =H12/E12 -> 1.0686275 | G12: =H12/(C12/1000) -> 13.385401 | H12: ='TikTok Ads Raw Data'!D12 -> 1090 | I12: =J12/E12 -> 0.019607843 | J12: ='TikTok Ads Raw Data'!E12 -> 20 | K12: =L12/J12 -> 214.25 | L12: ='TikTok Ads Raw Data'!F12 -> 4285
A13: ='TikTok Ads Raw Data'!A13 -> 45669 | B13: =MONTH(A:A) -> 1 | C13: ='TikTok Ads Raw Data'!B13 -> 86724 | D13: =E13/C13 -> 0.01854158 | E13: ='TikTok Ads Raw Data'!C13 -> 1608 | F13: =H13/E13 -> 1.011194 | G13: =H13/(C13/1000) -> 18.749135 | H13: ='TikTok Ads Raw Data'!D13 -> 1626 | I13: =J13/E13 -> 0.012437811 | J13: ='TikTok Ads Raw Data'!E13 -> 20 | K13: =L13/J13 -> 213.3 | L13: ='TikTok Ads Raw Data'!F13 -> 4266
... A366: ='TikTok Ads Raw Data'!A366 -> 46022 | B366: =MONTH(A:A) -> 12 | C366: ='TikTok Ads Raw Data'!B366 -> 79467 | D366: =E366/C366 -> 0.025192847 | E366: ='TikTok Ads Raw Data'!C366 -> 2002 | F366: =H366/E366 -> 1.0304695 | G366: =H366/(C366/1000) -> 25.960462 | H366: ='TikTok Ads Raw Data'!D366 -> 2063 | I366: =J366/E366 -> 0.022977023 | J366: ='TikTok Ads Raw Data'!E366 -> 46 | K366: =L366/J366 -> 130.28261 | L366: ='TikTok Ads Raw Data'!F366 -> 5993

Sheet Tiktok Ads Monthly
A1: Month | B1: Impressions | C1: Clicks | D1: Spend | E1: Conversions | F1: Revenue | G1: Avg. conversion amount | H1: ROAS | I1: CPC | J1: CPM | K1: CPA
A2: 1 | B2: =SUMIF('Tiktok Ads Performance Metrics'!B:B,A2,'Tiktok Ads Performance Metrics'!C:C) -> 2112620 | C2: =SUMIF('Tiktok Ads Performance Metrics'!B:B,A2,'Tiktok Ads Performance Metrics'!E:E) -> 41019 | D2: =SUMIF('Tiktok Ads Performance Metrics'!B:B,A2,'Tiktok Ads Performance Metrics'!H:H) -> 40140 | E2: =SUMIF('Tiktok Ads Performance Metrics'!B:B,A2,'Tiktok Ads Performance Metrics'!J:J) -> 739 | F2: =SUMIF('Tiktok Ads Performance Metrics'!B:B,A2,'Tiktok Ads Performance Metrics'!L:L) -> 124409 | G2: =F2/E2 -> 168.34777 | H2: =F2/D2 -> 3.0993772 | I2: =D2/C2 -> 0.97857091 | J2: =D2/(B2/1000) -> 19.000104 | K2: =D2/E2 -> 54.316644
A3: 2 | B3: =SUMIF('Tiktok Ads Performance Metrics'!B:B,A3,'Tiktok Ads Performance Metrics'!C:C) -> 1949003 | C3: =SUMIF('Tiktok Ads Performance Metrics'!B:B,A3,'Tiktok Ads Performance Metrics'!E:E) -> 39714 | D3: =SUMIF('Tiktok Ads Performance Metrics'!B:B,A3,'Tiktok Ads Performance Metrics'!H:H) -> 37924 | E3: =SUMIF('Tiktok Ads Performance Metrics'!B:B,A3,'Tiktok Ads Performance Metrics'!J:J) -> 675 | F3: =SUMIF('Tiktok Ads Performance Metrics'!B:B,A3,'Tiktok Ads Performance Metrics'!L:L) -> 113330 | G3: =F3/E3 -> 167.8963 | H3: =F3/D3 -> 2.9883451 | I3: =D3/C3 -> 0.95492773 | J3: =D3/(B3/1000) -> 19.458154 | K3: =D3/E3 -> 56.183704
A4: 3 | B4: =SUMIF('Tiktok Ads Performance Metrics'!B:B,A4,'Tiktok Ads Performance Metrics'!C:C) -> 1893765 | C4: =SUMIF('Tiktok Ads Performance Metrics'!B:B,A4,'Tiktok Ads Performance Metrics'!E:E) -> 39636 | D4: =SUMIF('Tiktok Ads Performance Metrics'!B:B,A4,'Tiktok Ads Performance Metrics'!H:H) -> 37093 | E4: =SUMIF('Tiktok Ads Performance Metrics'!B:B,A4,'Tiktok Ads Performance Metrics'!J:J) -> 745 | F4: =SUMIF('Tiktok Ads Performance Metrics'!B:B,A4,'Tiktok Ads Performance Metrics'!L:L) -> 116041 | G4: =F4/E4 -> 155.75973 | H4: =F4/D4 -> 3.12838 | I4: =D4/C4 -> 0.93584115 | J4: =D4/(B4/1000) -> 19.586908 | K4: =D4/E4 -> 49.789262
A5: 4 | B5: =SUMIF('Tiktok Ads Performance Metrics'!B:B,A5,'Tiktok Ads Performance Metrics'!C:C) -> 2282519 | C5: =SUMIF('Tiktok Ads Performance Metrics'!B:B,A5,'Tiktok Ads Performance Metrics'!E:E) -> 47400 | D5: =SUMIF('Tiktok Ads Performance Metrics'!B:B,A5,'Tiktok Ads Performance Metrics'!H:H) -> 47533 | E5: =SUMIF('Tiktok Ads Performance Metrics'!B:B,A5,'Tiktok Ads Performance Metrics'!J:J) -> 887 | F5: =SUMIF('Tiktok Ads Performance Metrics'!B:B,A5,'Tiktok Ads Performance Metrics'!L:L) -> 138187 | G5: =F5/E5 -> 155.79143 | H5: =F5/D5 -> 2.9071803 | I5: =D5/C5 -> 1.0028059 | J5: =D5/(B5/1000) -> 20.824799 | K5: =D5/E5 -> 53.588501
A6: 5 | B6: =SUMIF('Tiktok Ads Performance Metrics'!B:B,A6,'Tiktok Ads Performance Metrics'!C:C) -> 2165819 | C6: =SUMIF('Tiktok Ads Performance Metrics'!B:B,A6,'Tiktok Ads Performance Metrics'!E:E) -> 44964 | D6: =SUMIF('Tiktok Ads Performance Metrics'!B:B,A6,'Tiktok Ads Performance Metrics'!H:H) -> 46113 | E6: =SUMIF('Tiktok Ads Performance Metrics'!B:B,A6,'Tiktok Ads Performance Metrics'!J:J) -> 868 | F6: =SUMIF('Tiktok Ads Performance Metrics'!B:B,A6,'Tiktok Ads Performance Metrics'!L:L) -> 131777 | G6: =F6/E6 -> 151.81682 | H6: =F6/D6 -> 2.8576974 | I6: =D6/C6 -> 1.0255538 | J6: =D6/(B6/1000) -> 21.291253 | K6: =D6/E6 -> 53.125576
A7: 6 | B7: =SUMIF('Tiktok Ads Performance Metrics'!B:B,A7,'Tiktok Ads Performance Metrics'!C:C) -> 2051995 | C7: =SUMIF('Tiktok Ads Performance Metrics'!B:B,A7,'Tiktok Ads Performance Metrics'!E:E) -> 46469 | D7: =SUMIF('Tiktok Ads Performance Metrics'!B:B,A7,'Tiktok Ads Performance Metrics'!H:H) -> 45535 | E7: =SUMIF('Tiktok Ads Performance Metrics'!B:B,A7,'Tiktok Ads Performance Metrics'!J:J) -> 867 | F7: =SUMIF('Tiktok Ads Performance Metrics'!B:B,A7,'Tiktok Ads Performance Metrics'!L:L) -> 136097 | G7: =F7/E7 -> 156.97463 | H7: =F7/D7 -> 2.9888437 | I7: =D7/C7 -> 0.97990058 | J7: =D7/(B7/1000) -> 22.1906 | K7: =D7/E7 -> 52.520185
A8: 7 | B8: =SUMIF('Tiktok Ads Performance Metrics'!B:B,A8,'Tiktok Ads Performance Metrics'!C:C) -> 2321236 | C8: =SUMIF('Tiktok Ads Performance Metrics'!B:B,A8,'Tiktok Ads Performance Metrics'!E:E) -> 52304 | D8: =SUMIF('Tiktok Ads Performance Metrics'!B:B,A8,'Tiktok Ads Performance Metrics'!H:H) -> 45540 | E8: =SUMIF('Tiktok Ads Performance Metrics'!B:B,A8,'Tiktok Ads Performance Metrics'!J:J) -> 909 | F8: =SUMIF('Tiktok Ads Performance Metrics'!B:B,A8,'Tiktok Ads Performance Metrics'!L:L) -> 142209 | G8: =F8/E8 -> 156.44554 | H8: =F8/D8 -> 3.1227273 | I8: =D8/C8 -> 0.87067911 | J8: =D8/(B8/1000) -> 19.618858 | K8: =D8/E8 -> 50.09901
A9: 8 | B9: =SUMIF('Tiktok Ads Performance Metrics'!B:B,A9,'Tiktok Ads Performance Metrics'!C:C) -> 2515056 | C9: =SUMIF('Tiktok Ads Performance Metrics'!B:B,A9,'Tiktok Ads Performance Metrics'!E:E) -> 51908 | D9: =SUMIF('Tiktok Ads Performance Metrics'!B:B,A9,'Tiktok Ads Performance Metrics'!H:H) -> 44106 | E9: =SUMIF('Tiktok Ads Performance Metrics'!B:B,A9,'Tiktok Ads Performance Metrics'!J:J) -> 916 | F9: =SUMIF('Tiktok Ads Performance Metrics'!B:B,A9,'Tiktok Ads Performance Metrics'!L:L) -> 140844 | G9: =F9/E9 -> 153.75983 | H9: =F9/D9 -> 3.193307 | I9: =D9/C9 -> 0.84969562 | J9: =D9/(B9/1000) -> 17.536786 | K9: =D9/E9 -> 48.150655
A10: 9 | B10: =SUMIF('Tiktok Ads Performance Metrics'!B:B,A10,'Tiktok Ads Performance Metrics'!C:C) -> 1846314 | C10: =SUMIF('Tiktok Ads Performance Metrics'!B:B,A10,'Tiktok Ads Performance Metrics'!E:E) -> 36520 | D10: =SUMIF('Tiktok Ads Performance Metrics'!B:B,A10,'Tiktok Ads Performance Metrics'!H:H) -> 35760 | E10: =SUMIF('Tiktok Ads Performance Metrics'!B:B,A10,'Tiktok Ads Performance Metrics'!J:J) -> 682 | F10: =SUMIF('Tiktok Ads Performance Metrics'!B:B,A10,'Tiktok Ads Performance Metrics'!L:L) -> 107590 | G10: =F10/E10 -> 157.7566 | H10: =F10/D10 -> 3.0086689 | I10: =D10/C10 -> 0.97918949 | J10: =D10/(B10/1000) -> 19.36832 | K10: =D10/E10 -> 52.434018
A11: 10 | B11: =SUMIF('Tiktok Ads Performance Metrics'!B:B,A11,'Tiktok Ads Performance Metrics'!C:C) -> 2115203 | C11: =SUMIF('Tiktok Ads Performance Metrics'!B:B,A11,'Tiktok Ads Performance Metrics'!E:E) -> 45029 | D11: =SUMIF('Tiktok Ads Performance Metrics'!B:B,A11,'Tiktok Ads Performance Metrics'!H:H) -> 39690 | E11: =SUMIF('Tiktok Ads Performance Metrics'!B:B,A11,'Tiktok Ads Performance Metrics'!J:J) -> 858 | F11: =SUMIF('Tiktok Ads Performance Metrics'!B:B,A11,'Tiktok Ads Performance Metrics'!L:L) -> 127829 | G11: =F11/E11 -> 148.98485 | H11: =F11/D11 -> 3.2206853 | I11: =D11/C11 -> 0.88143197 | J11: =D11/(B11/1000) -> 18.764156 | K11: =D11/E11 -> 46.258741
A12: 11 | B12: =SUMIF('Tiktok Ads Performance Metrics'!B:B,A12,'Tiktok Ads Performance Metrics'!C:C) -> 1882573 | C12: =SUMIF('Tiktok Ads Performance Metrics'!B:B,A12,'Tiktok Ads Performance Metrics'!E:E) -> 39000 | D12: =SUMIF('Tiktok Ads Performance Metrics'!B:B,A12,'Tiktok Ads Performance Metrics'!H:H) -> 34809 | E12: =SUMIF('Tiktok Ads Performance Metrics'!B:B,A12,'Tiktok Ads Performance Metrics'!J:J) -> 690 | F12: =SUMIF('Tiktok Ads Performance Metrics'!B:B,A12,'Tiktok Ads Performance Metrics'!L:L) -> 111719 | G12: =F12/E12 -> 161.91159 | H12: =F12/D12 -> 3.2094861 | I12: =D12/C12 -> 0.89253846 | J12: =D12/(B12/1000) -> 18.49012 | K12: =D12/E12 -> 50.447826
A13: 12 | B13: =SUMIF('Tiktok Ads Performance Metrics'!B:B,A13,'Tiktok Ads Performance Metrics'!C:C) -> 1990299 | C13: =SUMIF('Tiktok Ads Performance Metrics'!B:B,A13,'Tiktok Ads Performance Metrics'!E:E) -> 44011 | D13: =SUMIF('Tiktok Ads Performance Metrics'!B:B,A13,'Tiktok Ads Performance Metrics'!H:H) -> 56662 | E13: =SUMIF('Tiktok Ads Performance Metrics'!B:B,A13,'Tiktok Ads Performance Metrics'!J:J) -> 1034 | F13: =SUMIF('Tiktok Ads Performance Metrics'!B:B,A13,'Tiktok Ads Performance Metrics'!L:L) -> 132858 | G13: =F13/E13 -> 128.48936 | H13: =F13/D13 -> 2.344746 | I13: =D13/C13 -> 1.2874509 | J13: =D13/(B13/1000) -> 28.469089 | K13: =D13/E13 -> 54.798839

Sheet Instagram Ads Monthly
A1: Month | B1: Impressions | C1: Clicks | D1: Spend | E1: Conversions | F1: Revenue | G1: Avg. conversion amount | H1: ROAS
A2: 1 | B2: =SUMIF('Instagram Ads Performance Metri'!B:B,A2,'Instagram Ads Performance Metri'!C:C) -> 1720107 | C2: =SUMIF('Instagram Ads Performance Metri'!B:B,A2,'Instagram Ads Performance Metri'!E:E) -> 32172 | D2: =SUMIF('Instagram Ads Performance Metri'!B:B,A2,'Instagram Ads Performance Metri'!H:H) -> 48783 | E2: =SUMIF('Instagram Ads Performance Metri'!B:B,A2,'Instagram Ads Performance Metri'!J:J) -> 599 | F2: =SUMIF('Instagram Ads Performance Metri'!B:B,A2,'Instagram Ads Performance Metri'!L:L) -> 99008 | G2: =F2/E2 -> 165.28881 | H2: =F2/D2 -> 2.0295595
A3: 2 | B3: =SUMIF('Instagram Ads Performance Metri'!B:B,A3,'Instagram Ads Performance Metri'!C:C) -> 1557121 | C3: =SUMIF('Instagram Ads Performance Metri'!B:B,A3,'Instagram Ads Performance Metri'!E:E) -> 31502 | D3: =SUMIF('Instagram Ads Performance Metri'!B:B,A3,'Instagram Ads Performance Metri'!H:H) -> 47406 | E3: =SUMIF('Instagram Ads Performance Metri'!B:B,A3,'Instagram Ads Performance Metri'!J:J) -> 546 | F3: =SUMIF('Instagram Ads Performance Metri'!B:B,A3,'Instagram Ads Performance Metri'!L:L) -> 92767 | G3: =F3/E3 -> 169.90293 | H3: =F3/D3 -> 1.956862
A4: 3 | B4: =SUMIF('Instagram Ads Performance Metri'!B:B,A4,'Instagram Ads Performance Metri'!C:C) -> 1570479 | C4: =SUMIF('Instagram Ads Performance Metri'!B:B,A4,'Instagram Ads Performance Metri'!E:E) -> 31937 | D4: =SUMIF('Instagram Ads Performance Metri'!B:B,A4,'Instagram Ads Performance Metri'!H:H) -> 45220 | E4: =SUMIF('Instagram Ads Performance Metri'!B:B,A4,'Instagram Ads Performance Metri'!J:J) -> 610 | F4: =SUMIF('Instagram Ads Performance Metri'!B:B,A4,'Instagram Ads Performance Metri'!L:L) -> 91252 | G4: =F4/E4 -> 149.59344 | H4: =F4/D4 -> 2.0179567
A5: 4 | B5: =SUMIF('Instagram Ads Performance Metri'!B:B,A5,'Instagram Ads Performance Metri'!C:C) -> 1921842 | C5: =SUMIF('Instagram Ads Performance Metri'!B:B,A5,'Instagram Ads Performance Metri'!E:E) -> 37631 | D5: =SUMIF('Instagram Ads Performance Metri'!B:B,A5,'Instagram Ads Performance Metri'!H:H) -> 59285 | E5: =SUMIF('Instagram Ads Performance Metri'!B:B,A5,'Instagram Ads Performance Metri'!J:J) -> 717 | F5: =SUMIF('Instagram Ads Performance Metri'!B:B,A5,'Instagram Ads Performance Metri'!L:L) -> 112373 | G5: =F5/E5 -> 156.72664 | H5: =F5/D5 -> 1.895471
A6: 5 | B6: =SUMIF('Instagram Ads Performance Metri'!B:B,A6,'Instagram Ads Performance Metri'!C:C) -> 1828461 | C6: =SUMIF('Instagram Ads Performance Metri'!B:B,A6,'Instagram Ads Performance Metri'!E:E) -> 36388 | D6: =SUMIF('Instagram Ads Performance Metri'!B:B,A6,'Instagram Ads Performance Metri'!H:H) -> 57348 | E6: =SUMIF('Instagram Ads Performance Metri'!B:B,A6,'Instagram Ads Performance Metri'!J:J) -> 702 | F6: =SUMIF('Instagram Ads Performance Metri'!B:B,A6,'Instagram Ads Performance Metri'!L:L) -> 106927 | G6: =F6/E6 -> 152.31766 | H6: =F6/D6 -> 1.8645288
A7: 6 | B7: =SUMIF('Instagram Ads Performance Metri'!B:B,A7,'Instagram Ads Performance Metri'!C:C) -> 1704404 | C7: =SUMIF('Instagram Ads Performance Metri'!B:B,A7,'Instagram Ads Performance Metri'!E:E) -> 36581 | D7: =SUMIF('Instagram Ads Performance Metri'!B:B,A7,'Instagram Ads Performance Metri'!H:H) -> 56754 | E7: =SUMIF('Instagram Ads Performance Metri'!B:B,A7,'Instagram Ads Performance Metri'!J:J) -> 716 | F7: =SUMIF('Instagram Ads Performance Metri'!B:B,A7,'Instagram Ads Performance Metri'!L:L) -> 113329 | G7: =F7/E7 -> 158.28073 | H7: =F7/D7 -> 1.996846
A8: 7 | B8: =SUMIF('Instagram Ads Performance Metri'!B:B,A8,'Instagram Ads Performance Metri'!C:C) -> 1631972 | C8: =SUMIF('Instagram Ads Performance Metri'!B:B,A8,'Instagram Ads Performance Metri'!E:E) -> 35440 | D8: =SUMIF('Instagram Ads Performance Metri'!B:B,A8,'Instagram Ads Performance Metri'!H:H) -> 54023 | E8: =SUMIF('Instagram Ads Performance Metri'!B:B,A8,'Instagram Ads Performance Metri'!J:J) -> 635 | F8: =SUMIF('Instagram Ads Performance Metri'!B:B,A8,'Instagram Ads Performance Metri'!L:L) -> 95572 | G8: =F8/E8 -> 150.50709 | H8: =F8/D8 -> 1.7690983
A9: 8 | B9: =SUMIF('Instagram Ads Performance Metri'!B:B,A9,'Instagram Ads Performance Metri'!C:C) -> 1673314 | C9: =SUMIF('Instagram Ads Performance Metri'!B:B,A9,'Instagram Ads Performance Metri'!E:E) -> 32435 | D9: =SUMIF('Instagram Ads Performance Metri'!B:B,A9,'Instagram Ads Performance Metri'!H:H) -> 50112 | E9: =SUMIF('Instagram Ads Performance Metri'!B:B,A9,'Instagram Ads Performance Metri'!J:J) -> 590 | F9: =SUMIF('Instagram Ads Performance Metri'!B:B,A9,'Instagram Ads Performance Metri'!L:L) -> 89404 | G9: =F9/E9 -> 151.5322 | H9: =F9/D9 -> 1.7840837
A10: 9 | B10: =SUMIF('Instagram Ads Performance Metri'!B:B,A10,'Instagram Ads Performance Metri'!C:C) -> 1486196 | C10: =SUMIF('Instagram Ads Performance Metri'!B:B,A10,'Instagram Ads Performance Metri'!E:E) -> 28665 | D10: =SUMIF('Instagram Ads Performance Metri'!B:B,A10,'Instagram Ads Performance Metri'!H:H) -> 43521 | E10: =SUMIF('Instagram Ads Performance Metri'!B:B,A10,'Instagram Ads Performance Metri'!J:J) -> 551 | F10: =SUMIF('Instagram Ads Performance Metri'!B:B,A10,'Instagram Ads Performance Metri'!L:L) -> 87196 | G10: =F10/E10 -> 158.25045 | H10: =F10/D10 -> 2.0035385
A11: 10 | B11: =SUMIF('Instagram Ads Performance Metri'!B:B,A11,'Instagram Ads Performance Metri'!C:C) -> 1780444 | C11: =SUMIF('Instagram Ads Performance Metri'!B:B,A11,'Instagram Ads Performance Metri'!E:E) -> 36765 | D11: =SUMIF('Instagram Ads Performance Metri'!B:B,A11,'Instagram Ads Performance Metri'!H:H) -> 49918 | E11: =SUMIF('Instagram Ads Performance Metri'!B:B,A11,'Instagram Ads Performance Metri'!J:J) -> 714 | F11: =SUMIF('Instagram Ads Performance Metri'!B:B,A11,'Instagram Ads Performance Metri'!L:L) -> 103574 | G11: =F11/E11 -> 145.06162 | H11: =F11/D11 -> 2.0748828
A12: 11 | B12: =SUMIF('Instagram Ads Performance Metri'!B:B,A12,'Instagram Ads Performance Metri'!C:C) -> 1567977 | C12: =SUMIF('Instagram Ads Performance Metri'!B:B,A12,'Instagram Ads Performance Metri'!E:E) -> 31184 | D12: =SUMIF('Instagram Ads Performance Metri'!B:B,A12,'Instagram Ads Performance Metri'!H:H) -> 42580 | E12: =SUMIF('Instagram Ads Performance Metri'!B:B,A12,'Instagram Ads Performance Metri'!J:J) -> 567 | F12: =SUMIF('Instagram Ads Performance Metri'!B:B,A12,'Instagram Ads Performance Metri'!L:L) -> 88344 | G12: =F12/E12 -> 155.80952 | H12: =F12/D12 -> 2.0747769
A13: 12 | B13: =SUMIF('Instagram Ads Performance Metri'!B:B,A13,'Instagram Ads Performance Metri'!C:C) -> 2294197 | C13: =SUMIF('Instagram Ads Performance Metri'!B:B,A13,'Instagram Ads Performance Metri'!E:E) -> 47640 | D13: =SUMIF('Instagram Ads Performance Metri'!B:B,A13,'Instagram Ads Performance Metri'!H:H) -> 69955 | E13: =SUMIF('Instagram Ads Performance Metri'!B:B,A13,'Instagram Ads Performance Metri'!J:J) -> 830 | F13: =SUMIF('Instagram Ads Performance Metri'!B:B,A13,'Instagram Ads Performance Metri'!L:L) -> 133509 | G13: =F13/E13 -> 160.85422 | H13: =F13/D13 -> 1.9084983

Sheet Pivot Tables
A1: INSTAGRAM | B1: Impressions | C1: Clicks | D1: Spend | E1: Conversions | F1: Revenue | G1: Avg. conversion amount | H1: ROAS
A3: Month | B3: SUM of Impressions | C3: SUM of Clicks | D3: SUM of Spend | E3: SUM of Conversions | F3: SUM of Revenue | G3: AVERAGE of Avg. conversion value | H3: SUM of Calculated Field 1
A4: 1 | B4: 1720107 | C4: 32172 | D4: 48783 | E4: 599 | F4: 99008 | G4: 167.82409 | H4: 2.0295595
A5: 2 | B5: 1557121 | C5: 31502 | D5: 47406 | E5: 546 | F5: 92767 | G5: 169.67085 | H5: 1.956862
A6: 3 | B6: 1570479 | C6: 31937 | D6: 45220 | E6: 610 | F6: 91252 | G6: 153.04983 | H6: 2.0179567
A7: 4 | B7: 1921842 | C7: 37631 | D7: 59285 | E7: 717 | F7: 112373 | G7: 153.41827 | H7: 1.895471
A8: 5 | B8: 1828461 | C8: 36388 | D8: 57348 | E8: 702 | F8: 106927 | G8: 150.86219 | H8: 1.8645288
A9: 6 | B9: 1704404 | C9: 36581 | D9: 56754 | E9: 716 | F9: 113329 | G9: 161.35832 | H9: 1.996846
A10: 7 | B10: 1631972 | C10: 35440 | D10: 54023 | E10: 635 | F10: 95572 | G10: 151.85947 | H10: 1.7690983
A11: 8 | B11: 1673314 | C11: 32435 | D11: 50112 | E11: 590 | F11: 89404 | G11: 151.93537 | H11: 1.7840837
A12: 9 | B12: 1486196 | C12: 28665 | D12: 43521 | E12: 551 | F12: 87196 | G12: 160.68104 | H12: 2.0035385
A13: 10 | B13: 1780444 | C13: 36765 | D13: 49918 | E13: 714 | F13: 103574 | G13: 151.76561 | H13: 2.0748828
A14: 11 | B14: 1567977 | C14: 31184 | D14: 42580 | E14: 567 | F14: 88344 | G14: 159.74063 | H14: 2.0747769
A15: 12 | B15: 2294197 | C15: 47640 | D15: 69955 | E15: 830 | F15: 133509 | G15: 164.29154 | H15: 1.9084983
A16: Grand Total | B16: 20736514 | C16: 418340 | D16: 624905 | E16: 7777 | F16: 1213255 | G16: 157.93414 | H16: 1.9415031
A20: TIKTOK | B20: Impressions | C20: Clicks | D20: Spend | E20: Conversions | F20: Revenue | G20: Avg. conversion amount | H20: ROAS
A21: Month | B21: SUM of Impressions | C21: SUM of Clicks | D21: SUM of Spend | E21: SUM of Conversions | F21: SUM of Revenue | G21: MEDIAN of Avg. conversion amount | H21: Calculated Field 1
A22: 1 | B22: 2112620 | C22: 41019 | D22: 40140 | E22: 739 | F22: 124409 | G22: 168.34777 | H22: 3.0993772
A23: 2 | B23: 1949003 | C23: 39714 | D23: 37924 | E23: 675 | F23: 113330 | G23: 167.8963 | H23: 2.9883451
A24: 3 | B24: 1893765 | C24: 39636 | D24: 37093 | E24: 745 | F24: 116041 | G24: 155.75973 | H24: 3.12838
A25: 4 | B25: 2282519 | C25: 47400 | D25: 47533 | E25: 887 | F25: 138187 | G25: 155.79143 | H25: 2.9071803
A26: 5 | B26: 2165819 | C26: 44964 | D26: 46113 | E26: 868 | F26: 131777 | G26: 151.81682 | H26: 2.8576974
A27: 6 | B27: 2051995 | C27: 46469 | D27: 45535 | E27: 867 | F27: 136097 | G27: 156.97463 | H27: 2.9888437
A28: 7 | B28: 2321236 | C28: 52304 | D28: 45540 | E28: 909 | F28: 142209 | G28: 156.44554 | H28: 3.1227273
A29: 8 | B29: 2515056 | C29: 51908 | D29: 44106 | E29: 916 | F29: 140844 | G29: 153.75983 | H29: 3.193307
A30: 9 | B30: 1846314 | C30: 36520 | D30: 35760 | E30: 682 | F30: 107590 | G30: 157.7566 | H30: 3.0086689
A31: 10 | B31: 2115203 | C31: 45029 | D31: 39690 | E31: 858 | F31: 127829 | G31: 148.98485 | H31: 3.2206853
A32: 11 | B32: 1882573 | C32: 39000 | D32: 34809 | E32: 690 | F32: 111719 | G32: 161.91159 | H32: 3.2094861
A33: 12 | B33: 1990299 | C33: 44011 | D33: 56662 | E33: 1034 | F33: 132858 | G33: 128.48936 | H33: 2.344746
A34: Grand Total | B34: 25126402 | C34: 527974 | D34: 510905 | E34: 9870 | F34: 1522890 | G34: 156.11849 | H34: 2.9807694
D37: {=_xludf.XLOOKUP(MAX(D22:D33),D22:D33,A22:A33)} -> #NAME?
D38: {=_xludf.XLOOKUP(MAX(E22:E33),E22:E33,A22:A33)} -> #NAME?
D39: {=_xludf.XLOOKUP(MAX(F22:F33),F22:F33,A22:A33)} -> #NAME?

Sheet Summary
A1: Q | B1: INSTAGRAM | C1: TIKTOK
A2: Bu yıl bu reklam kanalına toplam ne kadar harcadık? | B2: 624905 | C2: 510905
A3: Toplam kaç tıklama elde ettik? | B3: 418340 | C3: 527974
A4: Toplam kaç gösterim elde ettik? | B4: 20736514 | C4: 25126402
A5: Ortalama Tıklama Başına Maliyet (CPC) nedir? | B5: 1.51 | C5: 0.97
A6: Ortalama CPM nedir? | B6: 30.111913 | C6: 20.38
A7: Bu yıl kaç conversion (dönüşüm) elde ettik? | B7: 7777 | C7: 9870
A8: Ortalama conversion başına maliyet nedir? | B8: 80.35 | C8: 51.81
A9: Bu yıl bu reklam kanalından elde edilen gelir ne kadar? | B9: 1213255 | C9: 1522890
A10: Bu yılki ROAS nedir? | B10: 1.94 | C10: 2.98
A11: Bütçemizin çoğunu hangi ayda harcadık? | B11: Aralik | C11: Aralik
A12: En çok conversion (dönüşüm) hangi ayda elde ettik? | B12: Aralik | C12: Aralik
A13: En çok geliri hangi ayda elde ettik? | B13: Aralik | C13: Temmuz
A14: En yüksek gelirli ay için CPC ne? | B14: 1.49 | C14: 0.87
A15: En yüksek gelirli ay için CPM ne? | B15: 30.09 | C15: 19.62
A16: O ay için ortalama donusum miktari? | B16: 160.28 | C16: 156.12
A18: Hangi kanala daha fazla para harcıyoruz? | B18: Instagram Ads’e daha fazla harcama yapıyoruz.
A19: Hangi kanal en iyi performansı gösteriyor? | B19: Tiktok’un ROAS’ı Instagram Ads’ten 1,06 daha yüksek
A20: İki kanal da iyi performanslarını aynı aylarda gösteriyorlar mı? | B20: Her ikisi de en yuksek karliligi ekim ayinda gerceklestiriyor
A22: İki kanal arasında bütçe dağılımında veya stratejide yapabileceğiniz olası değişiklikler. | B22: TikTok'un yıl boyunca ROAS'ı hep 3.00 civarında gezerken, 12. ayda (Aralık) sert bir düşüşle 2.34'e geriliyor.
B23: Yani TikTok, yıl sonuna doğru bütçeyi verimsiz kullanmaya başlıyor. Bu yüzden o dönemde TikTok'un bütçesini kısmak mantikli olacak.
B25: Temmuz (7. ay) ve Ağustos (8. ay) aylarında TikTok'un ROAS değerleri sırasıyla 3.12 ve 3.19 ile zirve yapıyor.
B26: Yani yatırdığımiz parayı fazlasıyla geri veriyor. Bu iki ayda TikTok'a daha fazla bütçe vermek kasayı doldurur.
B28: Genel toplama (Grand Total) baktığında; Instagram'ın yıllık ROAS'ı 1.94 iken, TikTok'unki 2.99.
B29: Yani genel anlamda TikTok, Instagram'a göre yaklaşık %50 daha kârlı bir kanal.
B30: Bu yüzden yıl genelinde parayı Instagram'dan söküp TikTok'a yatırmak doğru bir stratejidir.

Sheet Graphs
